
<robot name="robot">

  <material name="blue">
  <color rgba="0 0 1 1"/>
  </material>

  <material name="green">
  <color rgba="0 1 0 1"/>
  </material>

  <material name="red">
  <color rgba=".5 0. 0 1"/>
  </material>


  <link name="trees">
    <visual>
      <origin xyz=" 2 -.8 -.7" rpy="0 0 1.5707"/>
      <geometry>
        <mesh filename="package://meshes/trees.stl" scale=".001 .001 .001"/>
      </geometry>
      <material name="brown">
        <color rgba=".58 .3 0 1.0"/>
      </material>
    </visual>
    <collision>
      <origin xyz=" 1.3 -.8 -.7" rpy="0 0 1.5707"/>
      <geometry>
        <mesh filename="package://meshes/trees.stl" scale=".001 .001 .001"/>
      </geometry>
    </collision>
  </link>


<link name="world"/>
  <link name="link1">
    <visual>
      <geometry>
        <box size="0.03 2.2 0.03"/>
      </geometry>
      <origin rpy="0 0 0" xyz="0 0 0"/>
      <material name="blue"/>
    </visual>
  </link>

  <link name="link2">
    <visual>
      <geometry>
        <box size="1.2 .03 0.03"/>
      </geometry>
      <origin rpy="0 0 0" xyz="0 0 0.03"/>
      <material name="green"/>
    </visual>
  </link>

  <link name="link3">
    <visual>
      <geometry>
        <box size=".03 .03 2"/>
      </geometry>
      <origin rpy="0 0 0" xyz="0 0. 1.045"/>
      <material name="red"/>
    </visual>
  </link>
  <link name="link_3_4">
    <visual>
      <geometry>
        <box size=".14 0.03 0.03"/>
      </geometry>
      <origin rpy="0 0 0" xyz=".06 0 0.06"/>
      <material name="blue"/>
    </visual>
  </link>

  <link name="link4">
    <visual>
      <geometry>
        <cylinder length="0.06" radius="0.02"/>
      </geometry>
      <material name="blue"/>
      <origin rpy="0 0 0" xyz="0.1 0. 0.09"/>
    </visual>
  </link>
  <link name="link_4_5">
    <visual>
      <geometry>
        <box size=".14 0.03 0.03"/>
      </geometry>
      <origin rpy="0 0 0" xyz=".06 0 0.01"/>
      <material name="blue"/>
    </visual>
  </link>

  <link name="link5">
    <visual>
      <geometry>
        <cylinder length="0.06" radius="0.02"/>
      </geometry>
      <material name="green"/>
      <origin rpy="0 1.5707 0" xyz="0.15 0. 0.015"/>
    </visual>
  </link>

  <link name="link_5_6">
    <visual>
      <geometry>
        <box size=".14 0.03 0.03"/>
      </geometry>
      <origin rpy="0 0 0" xyz=".06 0 0.01"/>
      <material name="green"/>
    </visual>
  </link>

  <link name="link6">
    <visual>
      <geometry>
        <cylinder length="0.06" radius="0.02"/>
      </geometry>
      <material name="red"/>
      <origin rpy="0 1.5707 0" xyz="0.13 0.015 0"/>
    </visual>
  </link>

  <link name="link7">
    <visual>
      <geometry>
        <box size=".03 .03 .1"/>
      </geometry>
      <origin rpy="0 0 0" xyz="0 0 0.05"/>
      <material name="red"/>
    </visual>
  </link>

  <joint name="world_tree_fixed_joint" type="fixed">
    <parent link="world" />
    <child link="trees"/>
    <origin xyz="0 0 0" rpy="0.0 0.0 0.0"/>
  </joint>

  <joint name="base_joint" type="fixed">
    <parent link="world"/>
    <child link="link1"/>
    <origin xyz="0 1 0" rpy="0 0 0" />
    <axis xyz="0 0 0" />
  </joint>


  <joint name="joint1" type="prismatic">
    <parent link="link1"/>
    <child link="link2"/>
    <origin xyz=".5 -.99 0" rpy="0 0 0" />
    <axis xyz="0 1 0" />
    <limit effort="1000.0" lower="0" upper="2" velocity="0.2"/>
  </joint>

  <joint name="joint2" type="prismatic">
    <parent link="link2"/>
    <child link="link3"/>
    <origin xyz="-.5 0 0" rpy="0 0 0" />
    <axis xyz="1 0 0" />
    <limit effort="1000.0" lower="0" upper="1" velocity="0.2"/>
  </joint>



  <joint name="joint3" type="prismatic">
    <parent link="link3"/>
    <child link="link_3_4"/>
    <origin xyz="0 0 0" rpy="0 0 0" />
    <axis xyz="0 0 1" />
    <limit effort="1000.0" lower="0" upper="2" velocity="0.2"/>
  </joint>

  <joint name="joint_3_4" type="fixed">
    <parent link="link_3_4"/>
    <child link="link4"/>
    <origin xyz="0 0 0" rpy="0 0 0" />
    </joint>

  <joint name="joint4" type="revolute">
    <parent link="link4"/>
    <child link="link_4_5"/>
    <origin rpy="0 0 0" xyz="0.1 0. 0.09"/>
    <axis xyz="0 0 1" />
    <limit effort="150.0" lower="-6.28318530718" upper="6.28318530718" velocity="3.14"/>
    <dynamics damping="0.0" friction="0.0"/>
  </joint>

  <joint name="joint_4_5" type="fixed">
    <parent link="link_4_5"/>
    <child link="link5"/>
    <origin xyz="0 0 0" rpy="0 0 0" />
    </joint>

  <joint name="joint5" type="revolute">
    <parent link="link5"/>
    <child link="link_5_6"/>
    <origin rpy="0 1.5707 0" xyz="0.15 0. 0.015"/>
    <axis xyz="0 0 1" />
    <limit effort="150.0" lower="-6.28318530718" upper="6.28318530718" velocity="3.14"/>
    <dynamics damping="0.0" friction="0.0"/>
  </joint>

  <joint name="joint_5_6" type="fixed">
    <parent link="link_5_6"/>
    <child link="link6"/>
    <origin xyz="0 0 0" rpy="0 0 0" />
    </joint>

  <joint name="joint6" type="revolute">
    <parent link="link6"/>
    <child link="link7"/>
    <origin rpy="0 1.5707 0" xyz="0.13 0.015 0."/>
    <axis xyz="0 0 1" />
    <limit effort="150.0" lower="-6.28318530718" upper="6.28318530718" velocity="3.14"/>
    <dynamics damping="0.0" friction="0.0"/>

  </joint>
</robot>
